<?xml version="1.0" encoding="utf-8"?>
<!-- =================================================================================== -->
<!-- |    This document was autogenerated by xacro from Balloon.xacro                  | -->
<!-- |    EDITING THIS FILE BY HAND IS NOT RECOMMENDED                                 | -->
<!-- =================================================================================== -->
<robot name="Kumara">
  <gazebo>
    <plugin filename="libgazebo_ros_control.so" name="gazebo_ros_control">
      <robotNamespace>/kumara</robotNamespace>
    </plugin>
    <!-- <plugin name="gazebo_cosim" filename="~/GazeboPlugin/export/lib/libGazeboCoSimPlugin.so">
            <portNumber>14581</portNumber>
        </plugin> -->
  </gazebo>
  <gazebo reference="chassis">
    <mu1>0</mu1>
    <mu2>0</mu2>
    <!-- <dampingFactor> 0.4 </dampingFactor> -->
    <material>Gazebo/Grey</material>
  </gazebo>
  <gazebo reference="arm_base">
    <mu1>0.3</mu1>
    <mu2>0.3</mu2>
    <!-- <dampingFactor> 0.1 </dampingFactor> -->
    <material>Gazebo/Grey</material>
  </gazebo>
  <gazebo reference="link_1">
    <mu1>0.3</mu1>
    <mu2>0.3</mu2>
    <!-- <dampingFactor> 0.1 </dampingFactor> -->
    <material>Gazebo/Grey</material>
  </gazebo>
  <gazebo reference="link_2">
    <mu1>0.3</mu1>
    <mu2>0.3</mu2>
    <!-- <dampingFactor> 0.1 </dampingFactor> -->
    <material>Gazebo/Grey</material>
  </gazebo>
  <gazebo reference="link_3">
    <mu1>0.3</mu1>
    <mu2>0.3</mu2>
    <!-- <dampingFactor> 0.1 </dampingFactor> -->
    <material>Gazebo/Grey</material>
  </gazebo>
  <gazebo reference="link_4">
    <mu1>0.3</mu1>
    <mu2>0.3</mu2>
    <!-- <dampingFactor> 0.1 </dampingFactor> -->
    <material>Gazebo/Grey</material>
  </gazebo>
  <gazebo reference="link_5">
    <mu1>0.3</mu1>
    <mu2>0.3</mu2>
    <!-- <dampingFactor> 0.1 </dampingFactor> -->
    <material>Gazebo/Grey</material>
  </gazebo>
  <link name="arm_base">
    <inertial>
      <mass value="1"/>
      <inertia ixx="0.26" ixy="0" ixz="0" iyy="0.26" iyz="0" izz="0.01"/>
    </inertial>
    <visual>
      <geometry>
        <mesh filename="package://kumara_description/meshes/arm/base_link.STL" scale="1 1 1"/>
      </geometry>
    </visual>
  </link>
  <link name="link_1">
    <inertial>
      <origin rpy="1.57079632679 0 0" xyz="0 0 0.13764"/>
      <mass value="1"/>
      <inertia ixx="0.26" ixy="0" ixz="0" iyy="0.26" iyz="0" izz="0.01"/>
    </inertial>
    <visual>
      <origin rpy="1.57079632679 0 0" xyz="0 0 0.13764"/>
      <geometry>
        <mesh filename="package://kumara_description/meshes/arm/link_1.STL" scale="1 1 1"/>
      </geometry>
    </visual>
  </link>
  <link name="link_2">
    <inertial>
      <origin rpy="-1.57079632679 0 1.57079632679"/>
      <mass value="1"/>
      <inertia ixx="0.26" ixy="0" ixz="0" iyy="0.26" iyz="0" izz="0.01"/>
    </inertial>
    <visual>
      <origin rpy="-1.57079632679 0 1.57079632679"/>
      <geometry>
        <mesh filename="package://kumara_description/meshes/arm/link_2.STL" scale="1 1 1"/>
      </geometry>
    </visual>
  </link>
  <link name="link_3">
    <inertial>
      <origin rpy="-1.57079632679 0 -1.57079632679" xyz="0 0 0.27597"/>
      <mass value="1"/>
      <inertia ixx="0.26" ixy="0" ixz="0" iyy="0.26" iyz="0" izz="0.01"/>
    </inertial>
    <visual>
      <origin rpy="-1.57079632679 0 -1.57079632679" xyz="0 0 0.27597"/>
      <geometry>
        <mesh filename="package://kumara_description/meshes/arm/link_3.STL" scale="1 1 1"/>
      </geometry>
    </visual>
  </link>
  <link name="link_4">
    <inertial>
      <origin rpy="1.57079632679 0 1.57079632679"/>
      <mass value="1"/>
      <inertia ixx="0.26" ixy="0" ixz="0" iyy="0.26" iyz="0" izz="0.01"/>
    </inertial>
    <visual>
      <origin rpy="1.57079632679 0 1.57079632679"/>
      <geometry>
        <mesh filename="package://kumara_description/meshes/arm/link_4.STL" scale="1 1 1"/>
      </geometry>
    </visual>
  </link>
  <link name="link_5">
    <inertial>
      <origin xyz="0 0 0.14"/>
      <mass value="1"/>
      <inertia ixx="0.26" ixy="0" ixz="0" iyy="0.26" iyz="0" izz="0.01"/>
    </inertial>
    <visual>
      <origin xyz="0 0 0.14"/>
      <geometry>
        <mesh filename="package://kumara_description/meshes/arm/link_5.STL" scale="1 1 1"/>
      </geometry>
    </visual>
  </link>
  <joint name="parent_to_arm_base" type="fixed">
    <parent link="chassis"/>
    <child link="arm_base"/>
    <axis xyz="0 0 1"/>
    <origin rpy="1.57079632679 -1.57079632679 0" xyz="0.17717 -0.0752 0.97939"/>
    <dynamics damping="0.7"/>
    <limit effort="40" lower="-3.14159265359" upper="3.14159265359" velocity="1000"/>
  </joint>
  <joint name="arm_base_to_link_1" type="revolute">
    <parent link="arm_base"/>
    <child link="link_1"/>
    <axis xyz="0 0 1"/>
    <dynamics damping="0.7"/>
    <limit effort="40" lower="-3.14159265359" upper="3.14159265359" velocity="1000"/>
  </joint>
  <joint name="link_1_to_link_2" type="revolute">
    <parent link="link_1"/>
    <child link="link_2"/>
    <axis xyz="0 0 1"/>
    <origin rpy="1.57079632679 0 0" xyz="0 0 0.13764"/>
    <dynamics damping="0.7"/>
    <limit effort="40" lower="-3.14159265359" upper="3.14159265359" velocity="1000"/>
  </joint>
  <joint name="link_2_to_link_3" type="revolute">
    <parent link="link_2"/>
    <child link="link_3"/>
    <axis xyz="0 0 1"/>
    <origin rpy="-1.57079632679 0 1.57079632679"/>
    <dynamics damping="0.7"/>
    <limit effort="40" lower="-3.14159265359" upper="3.14159265359" velocity="1000"/>
  </joint>
  <joint name="link_3_to_link_4" type="revolute">
    <parent link="link_3"/>
    <child link="link_4"/>
    <axis xyz="0 0 1"/>
    <origin rpy="-1.57079632679 0 -1.57079632679" xyz="0 0 0.27597"/>
    <dynamics damping="0.7"/>
    <limit effort="40" lower="-3.14159265359" upper="3.14159265359" velocity="1000"/>
  </joint>
  <joint name="link_4_to_link_5" type="revolute">
    <parent link="link_4"/>
    <child link="link_5"/>
    <axis xyz="0 0 1"/>
    <origin rpy="1.57079632679 0 1.57079632679"/>
    <dynamics damping="0.7"/>
    <limit effort="40" lower="-3.14159265359" upper="3.14159265359" velocity="1000"/>
  </joint>
  <transmission name="tran1">
    <type>transmission_interface/SimpleTransmission</type>
    <joint name="arm_base_to_link_1">
      <hardwareInterface>hardware_interface/EffortJointInterface</hardwareInterface>
    </joint>
    <actuator name="motor1">
      <hardwareInterface>hardware_interface/EffortJointInterface</hardwareInterface>
      <mechanicalReduction>1</mechanicalReduction>
    </actuator>
  </transmission>
  <transmission name="tran2">
    <type>transmission_interface/SimpleTransmission</type>
    <joint name="link_1_to_link_2">
      <hardwareInterface>hardware_interface/EffortJointInterface</hardwareInterface>
    </joint>
    <actuator name="motor2">
      <hardwareInterface>hardware_interface/EffortJointInterface</hardwareInterface>
      <mechanicalReduction>1</mechanicalReduction>
    </actuator>
  </transmission>
  <transmission name="tran3">
    <type>transmission_interface/SimpleTransmission</type>
    <joint name="link_2_to_link_3">
      <hardwareInterface>hardware_interface/EffortJointInterface</hardwareInterface>
    </joint>
    <actuator name="motor3">
      <hardwareInterface>hardware_interface/EffortJointInterface</hardwareInterface>
      <mechanicalReduction>1</mechanicalReduction>
    </actuator>
  </transmission>
  <transmission name="tran4">
    <type>transmission_interface/SimpleTransmission</type>
    <joint name="link_3_to_link_4">
      <hardwareInterface>hardware_interface/EffortJointInterface</hardwareInterface>
    </joint>
    <actuator name="motor4">
      <hardwareInterface>hardware_interface/EffortJointInterface</hardwareInterface>
      <mechanicalReduction>1</mechanicalReduction>
    </actuator>
  </transmission>
  <transmission name="tran5">
    <type>transmission_interface/SimpleTransmission</type>
    <joint name="link_4_to_link_5">
      <hardwareInterface>hardware_interface/EffortJointInterface</hardwareInterface>
    </joint>
    <actuator name="motor5">
      <hardwareInterface>hardware_interface/EffortJointInterface</hardwareInterface>
      <mechanicalReduction>1</mechanicalReduction>
    </actuator>
  </transmission>
  <link name="base_x_axis_link">
    <inertial>
      <origin rpy="0.0 0 0" xyz="0 0 0"/>
      <mass value="1e-5"/>
      <inertia ixx="0" ixy="0.0" ixz="0.0" iyy="0" iyz="0.0" izz="0"/>
    </inertial>
    <visual>
      <origin rpy="0.0 0 0" xyz="0 0 0"/>
      <geometry>
        <box size="1e-6 1e-6 1e-6"/>
      </geometry>
    </visual>
  </link>
  <joint name="base_x_axis_joint" type="prismatic">
    <origin rpy="0.0 0.0 0.0" xyz="0 0 0"/>
    <parent link="world"/>
    <child link="base_x_axis_link"/>
    <axis xyz="1 0 0"/>
    <limit effort="10000" lower="-1000.0" upper="1000.0" velocity="1000"/>
    <dynamics damping="15"/>
  </joint>
  <link name="base_y_axis_link">
    <inertial>
      <origin rpy="0.0 0 0" xyz="0 0 0"/>
      <mass value="1e-5"/>
      <inertia ixx="0" ixy="0.0" ixz="0.0" iyy="0" iyz="0.0" izz="0"/>
    </inertial>
    <visual>
      <origin rpy="0.0 0 0" xyz="0 0 0"/>
      <geometry>
        <box size="1e-6 1e-6 1e-6"/>
      </geometry>
    </visual>
  </link>
  <joint name="base_y_axis_joint" type="prismatic">
    <origin rpy="0.0 0.0 0.0" xyz="0 0 0"/>
    <parent link="base_x_axis_link"/>
    <child link="base_y_axis_link"/>
    <axis xyz="0 1 0"/>
    <limit effort="10000" lower="-1000.0" upper="1000.0" velocity="1000"/>
    <dynamics damping="15"/>
  </joint>
  <joint name="base_z_axis_joint" type="continuous">
    <parent link="base_y_axis_link"/>
    <child link="base_footprint"/>
    <origin xyz="0 0 0"/>
    <axis xyz="0 0 1"/>
    <limit effort="10000" velocity="1000"/>
    <dynamics damping="8"/>
  </joint>
  <transmission name="base_x_drive">
    <type>transmission_interface/SimpleTransmission</type>
    <joint name="base_x_axis_joint">
      <hardwareInterface>hardware_interface/EffortJointInterface</hardwareInterface>
    </joint>
    <actuator name="base_x_prismatic">
      <hardwareInterface>hardware_interface/EffortJointInterface</hardwareInterface>
      <mechanicalReduction>1</mechanicalReduction>
    </actuator>
  </transmission>
  <transmission name="base_y_drive">
    <type>transmission_interface/SimpleTransmission</type>
    <joint name="base_y_axis_joint">
      <hardwareInterface>hardware_interface/EffortJointInterface</hardwareInterface>
    </joint>
    <actuator name="base_y_prismatic">
      <hardwareInterface>hardware_interface/EffortJointInterface</hardwareInterface>
      <mechanicalReduction>1</mechanicalReduction>
    </actuator>
  </transmission>
  <transmission name="base_z_drive">
    <type>transmission_interface/SimpleTransmission</type>
    <joint name="base_z_axis_joint">
      <hardwareInterface>hardware_interface/EffortJointInterface</hardwareInterface>
    </joint>
    <actuator name="base_z_revolute">
      <hardwareInterface>hardware_interface/EffortJointInterface</hardwareInterface>
      <mechanicalReduction>1</mechanicalReduction>
    </actuator>
  </transmission>
  <link name="neck_tran_x">
    <inertial>
      <origin rpy="0.0 0 0" xyz="0 0 0"/>
      <mass value="0.001"/>
      <inertia ixx="0" ixy="0.0" ixz="0.0" iyy="0" iyz="0.0" izz="0"/>
    </inertial>
    <visual>
      <origin rpy="0.0 0 0" xyz="0 0 0"/>
      <geometry>
        <box size="0.000001 0.000001 0.000001"/>
      </geometry>
    </visual>
  </link>
  <joint name="neck_tran_x_joint" type="prismatic">
    <origin rpy="0.0 0.0 0.0" xyz="0.17887 0 1.194"/>
    <parent link="chassis"/>
    <child link="neck_tran_x"/>
    <axis xyz="1 0 0"/>
    <limit effort="10000" lower="-0.059" upper="0.059" velocity="1000"/>
    <dynamics damping="2.0"/>
  </joint>
  <link name="neck_tran_z">
    <inertial>
      <origin rpy="0.0 0 0" xyz="0 0 0"/>
      <mass value="0.001"/>
      <inertia ixx="0" ixy="0.0" ixz="0.0" iyy="0" iyz="0.0" izz="0"/>
    </inertial>
    <visual>
      <origin rpy="0.0 0 0" xyz="0 0 0"/>
      <geometry>
        <box size="0.000001 0.000001 0.000001"/>
      </geometry>
    </visual>
  </link>
  <joint name="neck_tran_z_joint" type="prismatic">
    <origin rpy="0.0 0.0 0.0" xyz="0 0 0"/>
    <parent link="neck_tran_x"/>
    <child link="neck_tran_z"/>
    <axis xyz="0 0 1"/>
    <limit effort="10000" lower="-0.018" upper="0" velocity="1000"/>
    <dynamics damping="2.0"/>
  </joint>
  <link name="neck_rot_x">
    <inertial>
      <origin rpy="0.0 0 0" xyz="0 0 0"/>
      <mass value="0.01"/>
      <inertia ixx="0" ixy="0.0" ixz="0.0" iyy="0" iyz="0.0" izz="0"/>
    </inertial>
    <visual>
      <origin rpy="0.0 0 0" xyz="0 0 0"/>
      <geometry>
        <box size="0.000001 0.000001 0.000001"/>
      </geometry>
    </visual>
  </link>
  <joint name="neck_rot_x_joint" type="revolute">
    <origin rpy="0.0 0.0 0.0" xyz="0 0 0"/>
    <parent link="neck_tran_z"/>
    <child link="neck_rot_x"/>
    <axis xyz="1 0 0"/>
    <limit effort="10000" lower="-1.0472" upper="1.0472" velocity="1000"/>
    <dynamics damping="2.0"/>
  </joint>
  <link name="neck_rot_y">
    <inertial>
      <origin rpy="0.0 0 0" xyz="0 0 0"/>
      <mass value="0.01"/>
      <inertia ixx="0" ixy="0.0" ixz="0.0" iyy="0" iyz="0.0" izz="0"/>
    </inertial>
    <visual>
      <origin rpy="0.0 0 0" xyz="0 0 0"/>
      <geometry>
        <box size="0.000001 0.000001 0.000001"/>
      </geometry>
    </visual>
  </link>
  <joint name="neck_rot_y_joint" type="revolute">
    <origin rpy="0.0 0.0 0.0" xyz="0 0 0"/>
    <parent link="neck_rot_x"/>
    <child link="neck_rot_y"/>
    <axis xyz="0 1 0"/>
    <limit effort="10000" lower="-1.0472" upper="1.0472" velocity="1000"/>
    <dynamics damping="2.0"/>
  </joint>
  <link name="neck_rot_z">
    <inertial>
      <origin rpy="0.0 0 0" xyz="0 0 0"/>
      <mass value="0.01"/>
      <inertia ixx="0" ixy="0.0" ixz="0.0" iyy="0" iyz="0.0" izz="0"/>
    </inertial>
    <visual>
      <origin rpy="0.0 0 0" xyz="0 0 0"/>
      <geometry>
        <box size="0.000001 0.000001 0.000001"/>
      </geometry>
    </visual>
  </link>
  <joint name="neck_rot_z_joint" type="revolute">
    <origin rpy="0.0 0.0 0.0" xyz="0 0 0"/>
    <parent link="neck_rot_y"/>
    <child link="neck_rot_z"/>
    <axis xyz="0 0 1"/>
    <limit effort="10000" lower="-3.14159265359" upper="3.14159265359" velocity="1000"/>
    <dynamics damping="2.0"/>
  </joint>
  <joint name="neck_to_head_link" type="fixed">
    <parent link="neck_rot_z"/>
    <child link="head_link"/>
    <origin xyz="0 0 0"/>
  </joint>
  <transmission name="tran_neck_x">
    <type>transmission_interface/SimpleTransmission</type>
    <joint name="neck_tran_x_joint">
      <hardwareInterface>hardware_interface/EffortJointInterface</hardwareInterface>
    </joint>
    <actuator name="neck_motor_x">
      <hardwareInterface>hardware_interface/EffortJointInterface</hardwareInterface>
      <mechanicalReduction>1</mechanicalReduction>
    </actuator>
  </transmission>
  <transmission name="tran_neck_z">
    <type>transmission_interface/SimpleTransmission</type>
    <joint name="neck_tran_z_joint">
      <hardwareInterface>hardware_interface/EffortJointInterface</hardwareInterface>
    </joint>
    <actuator name="neck_motor_z">
      <hardwareInterface>hardware_interface/EffortJointInterface</hardwareInterface>
      <mechanicalReduction>1</mechanicalReduction>
    </actuator>
  </transmission>
  <transmission name="tran_neck_rx">
    <type>transmission_interface/SimpleTransmission</type>
    <joint name="neck_rot_x_joint">
      <hardwareInterface>hardware_interface/EffortJointInterface</hardwareInterface>
    </joint>
    <actuator name="neck_motor_rx">
      <hardwareInterface>hardware_interface/EffortJointInterface</hardwareInterface>
      <mechanicalReduction>1</mechanicalReduction>
    </actuator>
  </transmission>
  <transmission name="tran_neck_ry">
    <type>transmission_interface/SimpleTransmission</type>
    <joint name="neck_rot_y_joint">
      <hardwareInterface>hardware_interface/EffortJointInterface</hardwareInterface>
    </joint>
    <actuator name="neck_motor_ry">
      <hardwareInterface>hardware_interface/EffortJointInterface</hardwareInterface>
      <mechanicalReduction>1</mechanicalReduction>
    </actuator>
  </transmission>
  <transmission name="tran_neck_rz">
    <type>transmission_interface/SimpleTransmission</type>
    <joint name="neck_rot_z_joint">
      <hardwareInterface>hardware_interface/EffortJointInterface</hardwareInterface>
    </joint>
    <actuator name="neck_motor_rz">
      <hardwareInterface>hardware_interface/EffortJointInterface</hardwareInterface>
      <mechanicalReduction>1</mechanicalReduction>
    </actuator>
  </transmission>
  <joint name="camera_joint" type="fixed">
    <origin rpy="0 0 0" xyz="0.072 0 0.1257"/>
    <parent link="head_link"/>
    <child link="camera_link"/>
  </joint>
  <!-- Camera -->
  <link name="camera_link">
    <collision>
      <origin rpy="0 0 0" xyz="0 0 0"/>
      <geometry>
        <box size="0.01 0.01 0.01"/>
      </geometry>
    </collision>
    <visual>
      <origin rpy="0 0 0" xyz="0 0 0"/>
      <geometry>
        <mesh filename="package://kumara_description/meshes/zedmini_camera.STL" scale="1 1 1"/>
      </geometry>
    </visual>
    <inertial>
      <mass value="1e-5"/>
      <origin rpy="0 0 0" xyz="0 0 0"/>
      <inertia ixx="1e-6" ixy="0" ixz="0" iyy="1e-6" iyz="0" izz="1e-6"/>
    </inertial>
  </link>
  <gazebo reference="camera_link">
    <material>Gazebo/Black</material>
    <sensor name="camera1" type="camera">
      <update_rate>120.0</update_rate>
      <camera name="head">
        <horizontal_fov>1.94900918</horizontal_fov>
        <image>
          <width>2540</width>
          <height>720</height>
          <format>R8G8B8</format>
        </image>
        <clip>
          <near>0.035</near>
          <far>300</far>
        </clip>
        <noise>
          <type>gaussian</type>
          <!-- Noise is sampled independently per pixel on each frame.
                        That pixel's noise value is added to each of its color
                        channels, which at that point lie in the range [0,1]. -->
          <mean>0.0</mean>
          <stddev>0.007</stddev>
        </noise>
      </camera>
      <plugin filename="libgazebo_ros_camera.so" name="camera_controller">
        <alwaysOn>true</alwaysOn>
        <updateRate>0.0</updateRate>
        <cameraName>kumara/camera_head</cameraName>
        <imageTopicName>image</imageTopicName>
        <cameraInfoTopicName>camera_info</cameraInfoTopicName>
        <frameName>camera_link</frameName>
        <hackBaseline>0.07</hackBaseline>
        <distortionK1>0.0</distortionK1>
        <distortionK2>0.0</distortionK2>
        <distortionK3>0.0</distortionK3>
        <distortionT1>0.0</distortionT1>
        <distortionT2>0.0</distortionT2>
      </plugin>
    </sensor>
  </gazebo>
  <joint name="front_rplidar_joint" type="fixed">
    <origin rpy="0 0 0" xyz="0.27 0 0.03"/>
    <parent link="chassis"/>
    <child link="front_rplidar_link"/>
  </joint>
  <link name="front_rplidar_link">
    <visual>
      <origin rpy="0 0 0" xyz="0 0 -0.03"/>
      <geometry>
        <mesh filename="package://kumara_description/meshes/rplidar_a2.STL" scale="1 1 1"/>
      </geometry>
      <material name="grey"/>
    </visual>
    <inertial>
      <mass value="0.1"/>
      <origin rpy="0 0 0" xyz="0 0 0"/>
      <inertia ixx="1e-6" ixy="0" ixz="0" iyy="1e-6" iyz="0" izz="1e-6"/>
    </inertial>
  </link>
  <gazebo reference="front_rplidar_link">
    <material>Gazebo/Grey</material>
    <sensor name="front_rplidar_a2" type="ray">
      <pose>0 0 0 0 0 0</pose>
      <visualize>False</visualize>
      <update_rate>10</update_rate>
      <ray>
        <scan>
          <horizontal>
            <samples>800</samples>
            <resolution>1</resolution>
            <min_angle>-3.14159265359</min_angle>
            <max_angle>3.14159265359</max_angle>
          </horizontal>
        </scan>
        <range>
          <min>0.10</min>
          <max>12.0</max>
          <resolution>0.0174533</resolution>
        </range>
        <noise>
          <type>gaussian</type>
          <!-- Noise parameters based on published spec for Hokuyo laser
                            achieving "+-30mm" accuracy at range < 10m.  A mean of 0.0m and
                            stddev of 0.01m will put 99.7% of samples within 0.03m of the true
                            reading. -->
          <mean>0.0</mean>
          <stddev>0.01</stddev>
        </noise>
      </ray>
      <plugin filename="libgazebo_ros_laser.so" name="gazebo_ros_front_lidar">
        <topicName>/kumara/front_laser/scan</topicName>
        <frameName>front_rplidar_link</frameName>
      </plugin>
    </sensor>
  </gazebo>
  <joint name="left_sonar_joint" type="fixed">
    <origin rpy="0 0 1.57079632679" xyz="0 0.25 -0.05025"/>
    <parent link="chassis"/>
    <child link="left_sonar_link"/>
  </joint>
  <link name="left_sonar_link">
    <visual>
      <origin rpy="0 0 0" xyz="0 0 0"/>
      <geometry>
        <mesh filename="package://kumara_description/meshes/ultrasonicSensor.STL" scale="1 1 1"/>
      </geometry>
      <material name="grey"/>
    </visual>
    <inertial>
      <mass value="0.04"/>
      <origin rpy="0 0 0" xyz="0 0 0"/>
      <inertia ixx="1e-6" ixy="0" ixz="0" iyy="1e-6" iyz="0" izz="1e-6"/>
    </inertial>
  </link>
  <gazebo reference="left_sonar_link">
    <material>Gazebo/Grey</material>
    <sensor name="left_sonar" type="ray">
      <pose>0 0 0 0 0 0</pose>
      <visualize>True</visualize>
      <update_rate>50</update_rate>
      <ray>
        <scan>
          <horizontal>
            <samples>10</samples>
            <resolution>1</resolution>
            <min_angle>-0.04</min_angle>
            <max_angle>0.04</max_angle>
          </horizontal>
          <vertical>
            <samples>10</samples>
            <resolution>1</resolution>
            <min_angle>-0.04</min_angle>
            <max_angle>0.04</max_angle>
          </vertical>
        </scan>
        <range>
          <min>0.03</min>
          <max>4</max>
          <resolution>0.02</resolution>
        </range>
        <noise>
          <type>gaussian</type>
          <!-- Noise parameters based on published spec for Hokuyo laser
                            achieving "+-30mm" accuracy at range < 10m.  A mean of 0.0m and
                            stddev of 0.01m will put 99.7% of samples within 0.03m of the true
                            reading. -->
          <mean>0.0</mean>
          <stddev>0.01</stddev>
        </noise>
      </ray>
      <plugin filename="libgazebo_ros_range.so" name="gazebo_ros_left_sonar">
        <alwaysOn>true</alwaysOn>
        <updateRate>50</updateRate>
        <topicName>/kumara/left_sonar</topicName>
        <frameName>left_sonar_link</frameName>
        <radiation>ULTRASONIC</radiation>
        <fov>0.08</fov>
      </plugin>
    </sensor>
  </gazebo>
  <joint name="right_sonar_joint" type="fixed">
    <origin rpy="0 0 -1.57079632679" xyz="0 -0.25 -0.05025"/>
    <parent link="chassis"/>
    <child link="right_sonar_link"/>
  </joint>
  <link name="right_sonar_link">
    <visual>
      <origin rpy="0 0 0" xyz="0 0 0"/>
      <geometry>
        <mesh filename="package://kumara_description/meshes/ultrasonicSensor.STL" scale="1 1 1"/>
      </geometry>
      <material name="grey"/>
    </visual>
    <inertial>
      <mass value="0.04"/>
      <origin rpy="0 0 0" xyz="0 0 0"/>
      <inertia ixx="1e-6" ixy="0" ixz="0" iyy="1e-6" iyz="0" izz="1e-6"/>
    </inertial>
  </link>
  <gazebo reference="right_sonar_link">
    <material>Gazebo/Grey</material>
    <sensor name="right_sonar" type="ray">
      <pose>0 0 0 0 0 0</pose>
      <visualize>True</visualize>
      <update_rate>50</update_rate>
      <ray>
        <scan>
          <horizontal>
            <samples>10</samples>
            <resolution>1</resolution>
            <min_angle>-0.04</min_angle>
            <max_angle>0.04</max_angle>
          </horizontal>
          <vertical>
            <samples>10</samples>
            <resolution>1</resolution>
            <min_angle>-0.04</min_angle>
            <max_angle>0.04</max_angle>
          </vertical>
        </scan>
        <range>
          <min>0.03</min>
          <max>4</max>
          <resolution>0.02</resolution>
        </range>
        <noise>
          <type>gaussian</type>
          <!-- Noise parameters based on published spec for Hokuyo laser
                            achieving "+-30mm" accuracy at range < 10m.  A mean of 0.0m and
                            stddev of 0.01m will put 99.7% of samples within 0.03m of the true
                            reading. -->
          <mean>0.0</mean>
          <stddev>0.01</stddev>
        </noise>
      </ray>
      <plugin filename="libgazebo_ros_range.so" name="gazebo_ros_right_sonar">
        <alwaysOn>true</alwaysOn>
        <updateRate>50</updateRate>
        <topicName>/kumara/right_sonar</topicName>
        <frameName>right_sonar_link</frameName>
        <radiation>ULTRASONIC</radiation>
        <fov>0.08</fov>
      </plugin>
    </sensor>
  </gazebo>
  <joint name="front_right_sonar_joint" type="fixed">
    <origin rpy="0 0 0" xyz="0.317 -0.173 -0.02525"/>
    <parent link="chassis"/>
    <child link="front_right_sonar_link"/>
  </joint>
  <link name="front_right_sonar_link">
    <visual>
      <origin rpy="0 0 0" xyz="0 0 0"/>
      <geometry>
        <mesh filename="package://kumara_description/meshes/ultrasonicSensor.STL" scale="1 1 1"/>
      </geometry>
      <material name="grey"/>
    </visual>
    <inertial>
      <mass value="0.04"/>
      <origin rpy="0 0 0" xyz="0 0 0"/>
      <inertia ixx="1e-6" ixy="0" ixz="0" iyy="1e-6" iyz="0" izz="1e-6"/>
    </inertial>
  </link>
  <gazebo reference="front_right_sonar_link">
    <material>Gazebo/Grey</material>
    <sensor name="front_right_sonar" type="ray">
      <pose>0 0 0 0 0 0</pose>
      <visualize>True</visualize>
      <update_rate>50</update_rate>
      <ray>
        <scan>
          <horizontal>
            <samples>10</samples>
            <resolution>1</resolution>
            <min_angle>-0.04</min_angle>
            <max_angle>0.04</max_angle>
          </horizontal>
          <vertical>
            <samples>10</samples>
            <resolution>1</resolution>
            <min_angle>-0.04</min_angle>
            <max_angle>0.04</max_angle>
          </vertical>
        </scan>
        <range>
          <min>0.03</min>
          <max>4</max>
          <resolution>0.02</resolution>
        </range>
        <noise>
          <type>gaussian</type>
          <!-- Noise parameters based on published spec for Hokuyo laser
                            achieving "+-30mm" accuracy at range < 10m.  A mean of 0.0m and
                            stddev of 0.01m will put 99.7% of samples within 0.03m of the true
                            reading. -->
          <mean>0.0</mean>
          <stddev>0.01</stddev>
        </noise>
      </ray>
      <plugin filename="libgazebo_ros_range.so" name="gazebo_ros_front_right_sonar">
        <alwaysOn>true</alwaysOn>
        <updateRate>50</updateRate>
        <topicName>/kumara/front_right_sonar</topicName>
        <frameName>front_right_sonar_link</frameName>
        <radiation>ULTRASONIC</radiation>
        <fov>0.08</fov>
      </plugin>
    </sensor>
  </gazebo>
  <joint name="front_left_sonar_joint" type="fixed">
    <origin rpy="0 0 0" xyz="0.317 0.173 -0.02525"/>
    <parent link="chassis"/>
    <child link="front_left_sonar_link"/>
  </joint>
  <link name="front_left_sonar_link">
    <visual>
      <origin rpy="0 0 0" xyz="0 0 0"/>
      <geometry>
        <mesh filename="package://kumara_description/meshes/ultrasonicSensor.STL" scale="1 1 1"/>
      </geometry>
      <material name="grey"/>
    </visual>
    <inertial>
      <mass value="0.04"/>
      <origin rpy="0 0 0" xyz="0 0 0"/>
      <inertia ixx="1e-6" ixy="0" ixz="0" iyy="1e-6" iyz="0" izz="1e-6"/>
    </inertial>
  </link>
  <gazebo reference="front_left_sonar_link">
    <material>Gazebo/Grey</material>
    <sensor name="front_left_sonar" type="ray">
      <pose>0 0 0 0 0 0</pose>
      <visualize>True</visualize>
      <update_rate>50</update_rate>
      <ray>
        <scan>
          <horizontal>
            <samples>10</samples>
            <resolution>1</resolution>
            <min_angle>-0.04</min_angle>
            <max_angle>0.04</max_angle>
          </horizontal>
          <vertical>
            <samples>10</samples>
            <resolution>1</resolution>
            <min_angle>-0.04</min_angle>
            <max_angle>0.04</max_angle>
          </vertical>
        </scan>
        <range>
          <min>0.03</min>
          <max>4</max>
          <resolution>0.02</resolution>
        </range>
        <noise>
          <type>gaussian</type>
          <!-- Noise parameters based on published spec for Hokuyo laser
                            achieving "+-30mm" accuracy at range < 10m.  A mean of 0.0m and
                            stddev of 0.01m will put 99.7% of samples within 0.03m of the true
                            reading. -->
          <mean>0.0</mean>
          <stddev>0.01</stddev>
        </noise>
      </ray>
      <plugin filename="libgazebo_ros_range.so" name="gazebo_ros_front_left_sonar">
        <alwaysOn>true</alwaysOn>
        <updateRate>50</updateRate>
        <topicName>/kumara/front_left_sonar</topicName>
        <frameName>front_left_sonar_link</frameName>
        <radiation>ULTRASONIC</radiation>
        <fov>0.08</fov>
      </plugin>
    </sensor>
  </gazebo>
  <joint name="back_right_sonar_joint" type="fixed">
    <origin rpy="0 0 3.14159265359" xyz="-0.317 -0.173 -0.02525"/>
    <parent link="chassis"/>
    <child link="back_right_sonar_link"/>
  </joint>
  <link name="back_right_sonar_link">
    <visual>
      <origin rpy="0 0 0" xyz="0 0 0"/>
      <geometry>
        <mesh filename="package://kumara_description/meshes/ultrasonicSensor.STL" scale="1 1 1"/>
      </geometry>
      <material name="grey"/>
    </visual>
    <inertial>
      <mass value="0.04"/>
      <origin rpy="0 0 0" xyz="0 0 0"/>
      <inertia ixx="1e-6" ixy="0" ixz="0" iyy="1e-6" iyz="0" izz="1e-6"/>
    </inertial>
  </link>
  <gazebo reference="back_right_sonar_link">
    <material>Gazebo/Grey</material>
    <sensor name="back_right_sonar" type="ray">
      <pose>0 0 0 0 0 0</pose>
      <visualize>True</visualize>
      <update_rate>50</update_rate>
      <ray>
        <scan>
          <horizontal>
            <samples>10</samples>
            <resolution>1</resolution>
            <min_angle>-0.04</min_angle>
            <max_angle>0.04</max_angle>
          </horizontal>
          <vertical>
            <samples>10</samples>
            <resolution>1</resolution>
            <min_angle>-0.04</min_angle>
            <max_angle>0.04</max_angle>
          </vertical>
        </scan>
        <range>
          <min>0.03</min>
          <max>4</max>
          <resolution>0.02</resolution>
        </range>
        <noise>
          <type>gaussian</type>
          <!-- Noise parameters based on published spec for Hokuyo laser
                            achieving "+-30mm" accuracy at range < 10m.  A mean of 0.0m and
                            stddev of 0.01m will put 99.7% of samples within 0.03m of the true
                            reading. -->
          <mean>0.0</mean>
          <stddev>0.01</stddev>
        </noise>
      </ray>
      <plugin filename="libgazebo_ros_range.so" name="gazebo_ros_back_right_sonar">
        <alwaysOn>true</alwaysOn>
        <updateRate>50</updateRate>
        <topicName>/kumara/back_right_sonar</topicName>
        <frameName>back_right_sonar_link</frameName>
        <radiation>ULTRASONIC</radiation>
        <fov>0.08</fov>
      </plugin>
    </sensor>
  </gazebo>
  <joint name="back_left_sonar_joint" type="fixed">
    <origin rpy="0 0 3.14159265359" xyz="-0.317 0.173 -0.02525"/>
    <parent link="chassis"/>
    <child link="back_left_sonar_link"/>
  </joint>
  <link name="back_left_sonar_link">
    <visual>
      <origin rpy="0 0 0" xyz="0 0 0"/>
      <geometry>
        <mesh filename="package://kumara_description/meshes/ultrasonicSensor.STL" scale="1 1 1"/>
      </geometry>
      <material name="grey"/>
    </visual>
    <inertial>
      <mass value="0.04"/>
      <origin rpy="0 0 0" xyz="0 0 0"/>
      <inertia ixx="1e-6" ixy="0" ixz="0" iyy="1e-6" iyz="0" izz="1e-6"/>
    </inertial>
  </link>
  <gazebo reference="back_left_sonar_link">
    <material>Gazebo/Grey</material>
    <sensor name="back_left_sonar" type="ray">
      <pose>0 0 0 0 0 0</pose>
      <visualize>True</visualize>
      <update_rate>50</update_rate>
      <ray>
        <scan>
          <horizontal>
            <samples>10</samples>
            <resolution>1</resolution>
            <min_angle>-0.04</min_angle>
            <max_angle>0.04</max_angle>
          </horizontal>
          <vertical>
            <samples>10</samples>
            <resolution>1</resolution>
            <min_angle>-0.04</min_angle>
            <max_angle>0.04</max_angle>
          </vertical>
        </scan>
        <range>
          <min>0.03</min>
          <max>4</max>
          <resolution>0.02</resolution>
        </range>
        <noise>
          <type>gaussian</type>
          <!-- Noise parameters based on published spec for Hokuyo laser
                            achieving "+-30mm" accuracy at range < 10m.  A mean of 0.0m and
                            stddev of 0.01m will put 99.7% of samples within 0.03m of the true
                            reading. -->
          <mean>0.0</mean>
          <stddev>0.01</stddev>
        </noise>
      </ray>
      <plugin filename="libgazebo_ros_range.so" name="gazebo_ros_back_left_sonar">
        <alwaysOn>true</alwaysOn>
        <updateRate>50</updateRate>
        <topicName>/kumara/back_left_sonar</topicName>
        <frameName>back_left_sonar_link</frameName>
        <radiation>ULTRASONIC</radiation>
        <fov>0.08</fov>
      </plugin>
    </sensor>
  </gazebo>
  <link name="world"/>
  <link name="base_footprint"/>
  <link name="chassis">
    <collision>
      <origin xyz="0 0 -0.115"/>
      <geometry>
        <box size="0.634 0.5 0.23"/>
      </geometry>
    </collision>
    <inertial>
      <origin xyz="0 0 -0.06"/>
      <mass value="28"/>
      <inertia ixx="0.89" ixy="0" ixz="0" iyy="1.1" iyz="0" izz="1.64"/>
    </inertial>
    <visual>
      <geometry>
        <mesh filename="package://kumara_description/meshes/base/kumaraBaseV2.STL" scale="1 1 1"/>
      </geometry>
    </visual>
  </link>
  <link name="body_link">
    <inertial>
      <origin xyz="0 0 0"/>
      <mass value="28"/>
      <inertia ixx="0.89" ixy="0" ixz="0" iyy="1.1" iyz="0" izz="1.64"/>
    </inertial>
    <visual>
      <geometry>
        <mesh filename="package://kumara_description/meshes/bodyPlaceHolderV1.STL" scale="1 1 1"/>
      </geometry>
    </visual>
  </link>
  <joint name="base_footprint_to_chassis" type="fixed">
    <parent link="base_footprint"/>
    <child link="chassis"/>
    <origin xyz="0 0 0.23"/>
  </joint>
  <joint name="chassis_to_body_link" type="fixed">
    <parent link="chassis"/>
    <child link="body_link"/>
    <origin xyz="0.1795 0 0"/>
  </joint>
  <link name="head_link">
    <collision>
      <origin xyz="0 0 0.07"/>
      <geometry>
        <box size="0.1765 0.227 0.1562"/>
      </geometry>
    </collision>
    <inertial>
      <origin xyz="0.03563 0.00117 0.02783"/>
      <mass value="1.3"/>
      <inertia ixx="0.0058440886" ixy="-0.0000726954" ixz="0.00046124" iyy="0.0077612567" iyz="0.00001826713" izz="0.006483092"/>
    </inertial>
    <visual>
      <geometry>
        <mesh filename="package://kumara_description/meshes/head/head.STL" scale="1 1 1"/>
      </geometry>
    </visual>
  </link>
  <gazebo reference="head_link">
    <material>Gazebo/Grey</material>
  </gazebo>
  <gazebo reference="body_link">
    <material>Gazebo/Grey</material>
  </gazebo>
</robot>

